Workbook

Sheet 光电传感器
A1: 光电传感器实验记录
A3: 光电表面
A6: 表面 | B6: 重复 | C6: 去程距离(cm) | D6: 回程距离(cm) | E6: 回程−去程(cm) | F6: 绝对差(cm)
A7: 粗糙 | B7: 1 | C7: 36.1 | D7: 35.9 | E7: =光电传感器!D7-光电传感器!C7 -> -0.2 | F7: =ABS(光电传感器!E7) -> 0.2
A8: 粗糙 | B8: 2 | C8: 35.8 | D8: 35.7 | E8: =光电传感器!D8-光电传感器!C8 -> -0.1 | F8: =ABS(光电传感器!E8) -> 0.1
A9: 粗糙 | B9: 3 | C9: 36.3 | D9: 36 | E9: =光电传感器!D9-光电传感器!C9 -> -0.3 | F9: =ABS(光电传感器!E9) -> 0.3
A10: 光面 | B10: 1 | C10: 52.2 | D10: 51.5 | E10: =光电传感器!D10-光电传感器!C10 -> -0.7 | F10: =ABS(光电传感器!E10) -> 0.7
A11: 光面 | B11: 2 | C11: 51.5 | D11: 54 | E11: =光电传感器!D11-光电传感器!C11 -> 2.5 | F11: =ABS(光电传感器!E11) -> 2.5
A12: 光面 | B12: 3 | C12: 53 | D12: 49.9 | E12: =光电传感器!D12-光电传感器!C12 -> -3.1 | F12: =ABS(光电传感器!E12) -> 3.1
A16: 表面 | B16: 去程均值cm | C16: 去程样本SD | D16: 回程均值cm | E16: 回程样本SD | F16: 平均绝对差cm
A17: 粗糙 | B17: =AVERAGE(光电传感器!C7:C9) -> 36.066667 | C17: =STDEV(光电传感器!C7:C9) -> 0.25166115 | D17: =AVERAGE(光电传感器!D7:D9) -> 35.866667 | E17: =STDEV(光电传感器!D7:D9) -> 0.15275252 | F17: =AVERAGE(光电传感器!F7:F9) -> 0.2
A18: 光面 | B18: =AVERAGE(光电传感器!C10:C12) -> 52.233333 | C18: =STDEV(光电传感器!C10:C12) -> 0.75055535 | D18: =AVERAGE(光电传感器!D10:D12) -> 51.8 | E18: =STDEV(光电传感器!D10:D12) -> 2.0663978 | F18: =AVERAGE(光电传感器!F10:F12) -> 2.1
A26: 光电角度
A28: 角度(°) | B28: 第1次测量(cm) | C28: 第2次测量(cm) | D28: 第3次测量(cm) | E28: 均值(cm) | F28: 样本标准差(cm)
A29: 15 | B29: 33.3 | C29: 33.8 | D29: 33.9 | E29: =AVERAGE(光电传感器!B29:D29) -> 33.666667 | F29: =STDEV(光电传感器!B29:D29) -> 0.32145503
A30: 30 | B30: 30 | C30: 30 | D30: 30.1 | E30: =AVERAGE(光电传感器!B30:D30) -> 30.033333 | F30: =STDEV(光电传感器!B30:D30) -> 0.057735027
A31: 45 | B31: 27.7 | C31: 27.8 | D31: 27.4 | E31: =AVERAGE(光电传感器!B31:D31) -> 27.633333 | F31: =STDEV(光电传感器!B31:D31) -> 0.2081666
A32: 60 | B32: 23.9 | C32: 24.4 | D32: 24.4 | E32: =AVERAGE(光电传感器!B32:D32) -> 24.233333 | F32: =STDEV(光电传感器!B32:D32) -> 0.28867513

Sheet 距离传感器
A1: 距离传感器实验记录
A3: 距离静态
A4: 速度=0；颜色、夹角、照明及每点采样量未记录。小数照原样保存，未假定它是均值。
A6: 间距cm | B6: 静态基准ADC
A7: 10 | B7: 2593.3
A8: 20 | B8: 1323.5
A9: 30 | B9: 859.45
A10: 40 | B10: 628.25
A11: 50 | B11: 489.5
A12: 60 | B12: 400.5
A13: 70 | B13: 325.2
A14: 80 | B14: 276.8
A24: 距离颜色
A27: 间距cm | B27: 基准_颜色未注 | C27: 白色ADC | D27: 黑色ADC | E27: 黑−白ADC | F27: 相对白色差异
A28: =距离传感器!A7 -> 10 | B28: =距离传感器!B7 -> 2593.3 | C28: 2589.85 | D28: 2601.2 | E28: =距离传感器!D28-距离传感器!C28 -> 11.35 | F28: =IFERROR(距离传感器!E28/距离传感器!C28,"") -> 0.0043824932
A29: =距离传感器!A8 -> 20 | B29: =距离传感器!B8 -> 1323.5 | C29: 1325.4 | D29: 1288.45 | E29: =距离传感器!D29-距离传感器!C29 -> -36.95 | F29: =IFERROR(距离传感器!E29/距离传感器!C29,"") -> -0.027878376
A30: =距离传感器!A9 -> 30 | B30: =距离传感器!B9 -> 859.45 | C30: 881.7 | D30: 869.95 | E30: =距离传感器!D30-距离传感器!C30 -> -11.75 | F30: =IFERROR(距离传感器!E30/距离传感器!C30,"") -> -0.013326528
A31: =距离传感器!A10 -> 40 | B31: =距离传感器!B10 -> 628.25 | C31: 640.35 | D31: 627.55 | E31: =距离传感器!D31-距离传感器!C31 -> -12.8 | F31: =IFERROR(距离传感器!E31/距离传感器!C31,"") -> -0.019989068
A32: =距离传感器!A11 -> 50 | B32: =距离传感器!B11 -> 489.5 | C32: 521.85 | D32: 493.3 | E32: =距离传感器!D32-距离传感器!C32 -> -28.55 | F32: =IFERROR(距离传感器!E32/距离传感器!C32,"") -> -0.054709208
A33: =距离传感器!A12 -> 60 | B33: =距离传感器!B12 -> 400.5 | C33: 404.45 | D33: 393.55 | E33: =距离传感器!D33-距离传感器!C33 -> -10.9 | F33: =IFERROR(距离传感器!E33/距离传感器!C33,"") -> -0.026950179
A34: =距离传感器!A13 -> 70 | B34: =距离传感器!B13 -> 325.2 | C34: 318.5 | D34: 306.3 | E34: =距离传感器!D34-距离传感器!C34 -> -12.2 | F34: =IFERROR(距离传感器!E34/距离传感器!C34,"") -> -0.038304553
A35: =距离传感器!A14 -> 80 | B35: =距离传感器!B14 -> 276.8 | C35: 275 | D35: 247.5 | E35: =距离传感器!D35-距离传感器!C35 -> -27.5 | F35: =IFERROR(距离传感器!E35/距离传感器!C35,"") -> -0.1
A45: 距离角度
A48: 间距cm | B48: 基准_夹角未注 | C48: 15° ADC | D48: 30° ADC | E48: 45° ADC
A49: =距离传感器!A7 -> 10 | B49: =距离传感器!B7 -> 2593.3 | C49: 2595.8 | D49: 2585.95 | E49: 2423.8
A50: =距离传感器!A8 -> 20 | B50: =距离传感器!B8 -> 1323.5 | C50: 1296.95 | D50: 1235.6 | E50: 1197.2
A51: =距离传感器!A9 -> 30 | B51: =距离传感器!B9 -> 859.45 | C51: 847.25 | D51: 820.7 | E51: 815.15
A52: =距离传感器!A10 -> 40 | B52: =距离传感器!B10 -> 628.25 | C52: 624.4 | D52: 597.95 | E52: 591.05
A53: =距离传感器!A11 -> 50 | B53: =距离传感器!B11 -> 489.5 | C53: 515.15 | D53: 464.8 | E53: 464.65
A54: =距离传感器!A12 -> 60 | B54: =距离传感器!B12 -> 400.5 | C54: 410.3 | D54: 393.85 | E54: 355.9
A55: =距离传感器!A13 -> 70 | B55: =距离传感器!B13 -> 325.2 | C55: 317.8 | D55: 302.25 | E55: 302.15
A56: =距离传感器!A14 -> 80 | B56: =距离传感器!B14 -> 276.8 | C56: 260.85 | D56: 283.1 | E56: 264.25
A66: 距离候选标定
A67: 候选模型 d=a/ADC+b，仅用于当前8点记录范围。下列是同点拟合残差，不是独立验证精度。
A69: 基准距离cm | B69: 基准ADC | C69: 1/ADC | D69: 模型距离cm | E69: 残差cm | F69: 绝对残差cm | G69: 残差平方 | K69: 参数 | L69: 值
A70: =距离传感器!A7 -> 10 | B70: =距离传感器!B7 -> 2593.3 | C70: =1/距离传感器!B70 -> 0.00038560907 | D70: =距离传感器!$L$70*距离传感器!C70+距离传感器!$L$71 -> 12.44541 | E70: =距离传感器!D70-距离传感器!A70 -> 2.4454102 | F70: =ABS(距离传感器!E70) -> 2.4454102 | G70: =距离传感器!E70^2 -> 5.9800308 | K70: a | L70: =SLOPE(距离传感器!A70:A77,距离传感器!C70:C77) -> 21632.584
A71: =距离传感器!A8 -> 20 | B71: =距离传感器!B8 -> 1323.5 | C71: =1/距离传感器!B71 -> 0.00075557235 | D71: =距离传感器!$L$70*距离传感器!C71+距离传感器!$L$71 -> 20.448672 | E71: =距离传感器!D71-距离传感器!A71 -> 0.44867198 | F71: =ABS(距离传感器!E71) -> 0.44867198 | G71: =距离传感器!E71^2 -> 0.20130654 | K71: b（cm） | L71: =INTERCEPT(距离传感器!A70:A77,距离传感器!C70:C77) -> 4.1036894
A72: =距离传感器!A9 -> 30 | B72: =距离传感器!B9 -> 859.45 | C72: =1/距离传感器!B72 -> 0.0011635348 | D72: =距离传感器!$L$70*距离传感器!C72+距离传感器!$L$71 -> 29.273955 | E72: =距离传感器!D72-距离传感器!A72 -> -0.72604538 | F72: =ABS(距离传感器!E72) -> 0.72604538 | G72: =距离传感器!E72^2 -> 0.52714189 | K72: 同点拟合RMSE cm | L72: =SQRT(AVERAGE(距离传感器!G70:G77)) -> 1.6114171
A73: =距离传感器!A10 -> 40 | B73: =距离传感器!B10 -> 628.25 | C73: =1/距离传感器!B73 -> 0.001591723 | D73: =距离传感器!$L$70*距离传感器!C73+距离传感器!$L$71 -> 38.536772 | E73: =距离传感器!D73-距离传感器!A73 -> -1.4632275 | F73: =ABS(距离传感器!E73) -> 1.4632275 | G73: =距离传感器!E73^2 -> 2.1410348 | K73: 同点最大绝对残差cm | L73: =MAX(距离传感器!F70:F77) -> 2.4454102
A74: =距离传感器!A11 -> 50 | B74: =距离传感器!B11 -> 489.5 | C74: =1/距离传感器!B74 -> 0.0020429009 | D74: =距离传感器!$L$70*距离传感器!C74+距离传感器!$L$71 -> 48.296916 | E74: =距离传感器!D74-距离传感器!A74 -> -1.703084 | F74: =ABS(距离传感器!E74) -> 1.703084 | G74: =距离传感器!E74^2 -> 2.9004949 | K74: 拟合点数 | L74: =COUNT(距离传感器!A70:A77) -> 8
...

Sheet 灰度传感器
A1: 灰度传感器实验记录
A3: 灰度距离
A4: 1最白、9最黑
A6: 色卡编号 | B6: 1cm ADC | C6: 3cm ADC | D6: 5cm ADC | E6: 15cm ADC
A7: 1 | B7: 2450 | C7: 1280 | D7: 455 | E7: 125
A8: 2 | B8: 2050 | C8: 1000 | D8: 355 | E8: 125
A9: 3 | B9: 1350 | C9: 880 | D9: 290 | E9: 110
A10: 4 | B10: 930 | C10: 640 | D10: 243 | E10: 96
A11: 5 | B11: 630 | C11: 460 | D11: 200 | E11: 85
A12: 6 | B12: 535 | C12: 335 | D12: 150 | E12: 80
A13: 7 | B13: 380 | C13: 245 | D13: 123 | E13: 68
A14: 8 | B14: 270 | C14: 150 | D14: 90 | E14: 65
A15: 9 | B15: 185 | C15: 113 | D15: 80 | E15: 65
A25: 灰度光照
A28: 色卡编号 | B28: 暗_3cm ADC | C28: 亮_3cm ADC | D28: 亮−暗ADC | E28: 相对暗差异
A29: 1 | B29: 1256 | C29: 1760 | D29: =灰度传感器!C29-灰度传感器!B29 -> 504 | E29: =IFERROR(灰度传感器!D29/灰度传感器!B29,"") -> 0.40127389
A30: 2 | B30: 959 | C30: 1347 | D30: =灰度传感器!C30-灰度传感器!B30 -> 388 | E30: =IFERROR(灰度传感器!D30/灰度传感器!B30,"") -> 0.40458811
A31: 3 | B31: 748 | C31: 1069 | D31: =灰度传感器!C31-灰度传感器!B31 -> 321 | E31: =IFERROR(灰度传感器!D31/灰度传感器!B31,"") -> 0.42914439
A32: 4 | B32: 554 | C32: 774 | D32: =灰度传感器!C32-灰度传感器!B32 -> 220 | E32: =IFERROR(灰度传感器!D32/灰度传感器!B32,"") -> 0.39711191
A33: 5 | B33: 419 | C33: 578 | D33: =灰度传感器!C33-灰度传感器!B33 -> 159 | E33: =IFERROR(灰度传感器!D33/灰度传感器!B33,"") -> 0.37947494
A34: 6 | B34: 351 | C34: 418 | D34: =灰度传感器!C34-灰度传感器!B34 -> 67 | E34: =IFERROR(灰度传感器!D34/灰度传感器!B34,"") -> 0.19088319
A35: 7 | B35: 263 | C35: 270 | D35: =灰度传感器!C35-灰度传感器!B35 -> 7 | E35: =IFERROR(灰度传感器!D35/灰度传感器!B35,"") -> 0.02661597
A36: 8 | B36: 218 | C36: 204 | D36: =灰度传感器!C36-灰度传感器!B36 -> -14 | E36: =IFERROR(灰度传感器!D36/灰度传感器!B36,"") -> -0.064220183
A37: 9 | B37: 175 | C37: 148 | D37: =灰度传感器!C37-灰度传感器!B37 -> -27 | E37: =IFERROR(灰度传感器!D37/灰度传感器!B37,"") -> -0.15428571
